2025-09-17 13:44:01,850 - INFO - [utils.py:50] - 日志系统初始化完成（控制台+文件轮转）
2025-09-17 13:44:02,269 - INFO - [utils.py:50] - 日志系统初始化完成（控制台+文件轮转）
2025-09-17 13:44:02,277 - INFO - [db_utils.py:370] - 数据库初始化完成
2025-09-17 13:44:02,277 - INFO - [app.py:86] - 数据库初始化/校验完成。
2025-09-17 13:44:02,279 - INFO - [db_utils.py:370] - 数据库初始化完成
2025-09-17 13:44:02,282 - INFO - [app.py:113] - 数据目录 './user_data' 已确保存在。
2025-09-17 13:44:56,034 - ERROR - [app.py:857] - admin_user_detail 失败: no such column: updated_at
Traceback (most recent call last):
  File "D:\item\KnowlEdge\src\app.py", line 793, in admin_user_detail
    user_row = cursor.execute("SELECT id, name, occupation, email, created_at, updated_at FROM users WHERE id=?", (user_id,)).fetchone()
sqlite3.OperationalError: no such column: updated_at
2025-09-17 13:44:57,182 - ERROR - [app.py:857] - admin_user_detail 失败: no such column: updated_at
Traceback (most recent call last):
  File "D:\item\KnowlEdge\src\app.py", line 793, in admin_user_detail
    user_row = cursor.execute("SELECT id, name, occupation, email, created_at, updated_at FROM users WHERE id=?", (user_id,)).fetchone()
sqlite3.OperationalError: no such column: updated_at
2025-09-17 13:44:58,005 - ERROR - [app.py:857] - admin_user_detail 失败: no such column: updated_at
Traceback (most recent call last):
  File "D:\item\KnowlEdge\src\app.py", line 793, in admin_user_detail
    user_row = cursor.execute("SELECT id, name, occupation, email, created_at, updated_at FROM users WHERE id=?", (user_id,)).fetchone()
sqlite3.OperationalError: no such column: updated_at
2025-09-17 13:44:58,780 - ERROR - [app.py:857] - admin_user_detail 失败: no such column: updated_at
Traceback (most recent call last):
  File "D:\item\KnowlEdge\src\app.py", line 793, in admin_user_detail
    user_row = cursor.execute("SELECT id, name, occupation, email, created_at, updated_at FROM users WHERE id=?", (user_id,)).fetchone()
sqlite3.OperationalError: no such column: updated_at
2025-09-17 13:44:59,330 - ERROR - [app.py:857] - admin_user_detail 失败: no such column: updated_at
Traceback (most recent call last):
  File "D:\item\KnowlEdge\src\app.py", line 793, in admin_user_detail
    user_row = cursor.execute("SELECT id, name, occupation, email, created_at, updated_at FROM users WHERE id=?", (user_id,)).fetchone()
sqlite3.OperationalError: no such column: updated_at
2025-09-17 13:44:59,986 - ERROR - [app.py:857] - admin_user_detail 失败: no such column: updated_at
Traceback (most recent call last):
  File "D:\item\KnowlEdge\src\app.py", line 793, in admin_user_detail
    user_row = cursor.execute("SELECT id, name, occupation, email, created_at, updated_at FROM users WHERE id=?", (user_id,)).fetchone()
sqlite3.OperationalError: no such column: updated_at
2025-09-17 13:45:00,298 - ERROR - [app.py:857] - admin_user_detail 失败: no such column: updated_at
Traceback (most recent call last):
  File "D:\item\KnowlEdge\src\app.py", line 793, in admin_user_detail
    user_row = cursor.execute("SELECT id, name, occupation, email, created_at, updated_at FROM users WHERE id=?", (user_id,)).fetchone()
sqlite3.OperationalError: no such column: updated_at
2025-09-17 13:45:11,938 - ERROR - [app.py:857] - admin_user_detail 失败: no such column: updated_at
Traceback (most recent call last):
  File "D:\item\KnowlEdge\src\app.py", line 793, in admin_user_detail
    user_row = cursor.execute("SELECT id, name, occupation, email, created_at, updated_at FROM users WHERE id=?", (user_id,)).fetchone()
sqlite3.OperationalError: no such column: updated_at
2025-09-17 13:45:12,512 - ERROR - [app.py:857] - admin_user_detail 失败: no such column: updated_at
Traceback (most recent call last):
  File "D:\item\KnowlEdge\src\app.py", line 793, in admin_user_detail
    user_row = cursor.execute("SELECT id, name, occupation, email, created_at, updated_at FROM users WHERE id=?", (user_id,)).fetchone()
sqlite3.OperationalError: no such column: updated_at
2025-09-17 13:54:49,194 - INFO - [utils.py:50] - 日志系统初始化完成（控制台+文件轮转）
2025-09-17 13:54:49,732 - INFO - [utils.py:50] - 日志系统初始化完成（控制台+文件轮转）
2025-09-17 13:54:49,740 - INFO - [db_utils.py:370] - 数据库初始化完成
2025-09-17 13:54:49,741 - INFO - [app.py:86] - 数据库初始化/校验完成。
2025-09-17 13:54:49,745 - INFO - [db_utils.py:370] - 数据库初始化完成
2025-09-17 13:54:49,748 - INFO - [app.py:113] - 数据目录 './user_data' 已确保存在。
2025-09-17 13:55:23,594 - ERROR - [app.py:883] - admin_user_detail 失败: no such column: updated_at
Traceback (most recent call last):
  File "D:\item\KnowlEdge\src\app.py", line 795, in admin_user_detail
    user_row = cursor.execute("SELECT id, name, occupation, email, created_at, updated_at FROM users WHERE id=?", (user_id,)).fetchone()
sqlite3.OperationalError: no such column: updated_at
2025-09-17 13:55:24,825 - ERROR - [app.py:883] - admin_user_detail 失败: no such column: updated_at
Traceback (most recent call last):
  File "D:\item\KnowlEdge\src\app.py", line 795, in admin_user_detail
    user_row = cursor.execute("SELECT id, name, occupation, email, created_at, updated_at FROM users WHERE id=?", (user_id,)).fetchone()
sqlite3.OperationalError: no such column: updated_at
2025-09-17 13:55:27,635 - ERROR - [app.py:883] - admin_user_detail 失败: no such column: updated_at
Traceback (most recent call last):
  File "D:\item\KnowlEdge\src\app.py", line 795, in admin_user_detail
    user_row = cursor.execute("SELECT id, name, occupation, email, created_at, updated_at FROM users WHERE id=?", (user_id,)).fetchone()
sqlite3.OperationalError: no such column: updated_at
2025-09-17 13:55:27,972 - ERROR - [app.py:883] - admin_user_detail 失败: no such column: updated_at
Traceback (most recent call last):
  File "D:\item\KnowlEdge\src\app.py", line 795, in admin_user_detail
    user_row = cursor.execute("SELECT id, name, occupation, email, created_at, updated_at FROM users WHERE id=?", (user_id,)).fetchone()
sqlite3.OperationalError: no such column: updated_at
2025-09-17 13:55:28,228 - ERROR - [app.py:883] - admin_user_detail 失败: no such column: updated_at
Traceback (most recent call last):
  File "D:\item\KnowlEdge\src\app.py", line 795, in admin_user_detail
    user_row = cursor.execute("SELECT id, name, occupation, email, created_at, updated_at FROM users WHERE id=?", (user_id,)).fetchone()
sqlite3.OperationalError: no such column: updated_at
2025-09-17 13:55:29,141 - ERROR - [app.py:883] - admin_user_detail 失败: no such column: updated_at
Traceback (most recent call last):
  File "D:\item\KnowlEdge\src\app.py", line 795, in admin_user_detail
    user_row = cursor.execute("SELECT id, name, occupation, email, created_at, updated_at FROM users WHERE id=?", (user_id,)).fetchone()
sqlite3.OperationalError: no such column: updated_at
2025-09-17 13:55:29,397 - ERROR - [app.py:883] - admin_user_detail 失败: no such column: updated_at
Traceback (most recent call last):
  File "D:\item\KnowlEdge\src\app.py", line 795, in admin_user_detail
    user_row = cursor.execute("SELECT id, name, occupation, email, created_at, updated_at FROM users WHERE id=?", (user_id,)).fetchone()
sqlite3.OperationalError: no such column: updated_at
2025-09-17 13:55:34,015 - ERROR - [app.py:883] - admin_user_detail 失败: no such column: updated_at
Traceback (most recent call last):
  File "D:\item\KnowlEdge\src\app.py", line 795, in admin_user_detail
    user_row = cursor.execute("SELECT id, name, occupation, email, created_at, updated_at FROM users WHERE id=?", (user_id,)).fetchone()
sqlite3.OperationalError: no such column: updated_at
2025-09-17 13:55:35,298 - ERROR - [app.py:883] - admin_user_detail 失败: no such column: updated_at
Traceback (most recent call last):
  File "D:\item\KnowlEdge\src\app.py", line 795, in admin_user_detail
    user_row = cursor.execute("SELECT id, name, occupation, email, created_at, updated_at FROM users WHERE id=?", (user_id,)).fetchone()
sqlite3.OperationalError: no such column: updated_at
2025-09-17 14:02:24,626 - INFO - [utils.py:50] - 日志系统初始化完成（控制台+文件轮转）
2025-09-17 14:02:25,081 - INFO - [utils.py:50] - 日志系统初始化完成（控制台+文件轮转）
2025-09-17 14:02:25,087 - INFO - [db_utils.py:370] - 数据库初始化完成
2025-09-17 14:02:25,087 - INFO - [app.py:86] - 数据库初始化/校验完成。
2025-09-17 14:02:25,090 - INFO - [db_utils.py:370] - 数据库初始化完成
2025-09-17 14:02:25,094 - INFO - [app.py:113] - 数据目录 './user_data' 已确保存在。
